[rospy.client][INFO] 2022-02-23 12:05:45,232: init_node, name[/rostopic_16397_1645617945169], pid[16397]
[xmlrpc][INFO] 2022-02-23 12:05:45,232: XML-RPC server binding to 0.0.0.0:0
[xmlrpc][INFO] 2022-02-23 12:05:45,232: Started XML-RPC server [http://FM00351-u:41373/]
[rospy.init][INFO] 2022-02-23 12:05:45,232: ROS Slave URI: [http://FM00351-u:41373/]
[rospy.impl.masterslave][INFO] 2022-02-23 12:05:45,233: _ready: http://FM00351-u:41373/
[xmlrpc][INFO] 2022-02-23 12:05:45,233: xml rpc node: starting XML-RPC server
[rospy.registration][INFO] 2022-02-23 12:05:45,233: Registering with master node http://localhost:11311
[rospy.init][INFO] 2022-02-23 12:05:45,333: registered with master
[rospy.rosout][INFO] 2022-02-23 12:05:45,333: initializing /rosout core topic
[rospy.rosout][INFO] 2022-02-23 12:05:45,337: connected to core topic /rosout
[rospy.simtime][INFO] 2022-02-23 12:05:45,338: /use_sim_time is not set, will not subscribe to simulated time [/clock] topic
[rospy.internal][INFO] 2022-02-23 12:05:45,400: topic[/rosout] adding connection to [http://FM00351-u:37407/], count 0
[rospy.internal][INFO] 2022-02-23 12:05:45,401: topic[/rosout] adding connection to [http://FM00351-u:35365/], count 0
[rospy.internal][INFO] 2022-02-23 12:05:45,401: topic[/rosout] adding connection to [http://FM00351-u:34949/], count 0
[rospy.internal][INFO] 2022-02-23 12:05:45,403: topic[/rosout] adding connection to [http://FM00351-u:41373/], count 1
[rospy.internal][INFO] 2022-02-23 12:05:45,404: topic[/rosout] adding connection to [/rostopic_16397_1645617945169], count 0
[rospy.internal][INFO] 2022-02-23 12:05:45,607: topic[/rosout] adding connection to [/rosout], count 1
[rospy.internal][ERROR] 2022-02-23 12:05:47,632: Unable to initiate TCP/IP socket to FM00351-u:43131 (http://FM00351-u:37407/): Traceback (most recent call last):
  File "/opt/ros/melodic/lib/python2.7/dist-packages/rospy/impl/tcpros_base.py", line 562, in connect
    self.read_header()
  File "/opt/ros/melodic/lib/python2.7/dist-packages/rospy/impl/tcpros_base.py", line 657, in read_header
    self._validate_header(read_ros_handshake_header(sock, self.read_buff, self.protocol.buff_size))
  File "/opt/ros/melodic/lib/python2.7/dist-packages/rospy/impl/tcpros_base.py", line 600, in _validate_header
    raise TransportInitError("remote error reported: %s"%header['error'])
TransportInitError: remote error reported: node shutting down

[rospy.internal][ERROR] 2022-02-23 12:05:47,632: Unable to initiate TCP/IP socket to FM00351-u:45243 (http://FM00351-u:35365/): Traceback (most recent call last):
  File "/opt/ros/melodic/lib/python2.7/dist-packages/rospy/impl/tcpros_base.py", line 562, in connect
    self.read_header()
  File "/opt/ros/melodic/lib/python2.7/dist-packages/rospy/impl/tcpros_base.py", line 657, in read_header
    self._validate_header(read_ros_handshake_header(sock, self.read_buff, self.protocol.buff_size))
  File "/opt/ros/melodic/lib/python2.7/dist-packages/rospy/impl/tcpros_base.py", line 600, in _validate_header
    raise TransportInitError("remote error reported: %s"%header['error'])
TransportInitError: remote error reported: node shutting down

[rospy.internal][WARNING] 2022-02-23 12:05:48,633: Unknown error initiating TCP/IP socket to FM00351-u:43131 (http://FM00351-u:37407/): Traceback (most recent call last):
  File "/opt/ros/melodic/lib/python2.7/dist-packages/rospy/impl/tcpros_base.py", line 560, in connect
    self.socket.connect((dest_addr, dest_port))
  File "/usr/lib/python2.7/socket.py", line 228, in meth
    return getattr(self._sock,name)(*args)
error: [Errno 111] Connection refused

[rospy.internal][INFO] 2022-02-23 12:05:48,634: topic[/rosout] removing connection to http://FM00351-u:37407/
[rospy.internal][WARNING] 2022-02-23 12:05:48,634: Unknown error initiating TCP/IP socket to FM00351-u:45243 (http://FM00351-u:35365/): Traceback (most recent call last):
  File "/opt/ros/melodic/lib/python2.7/dist-packages/rospy/impl/tcpros_base.py", line 560, in connect
    self.socket.connect((dest_addr, dest_port))
  File "/usr/lib/python2.7/socket.py", line 228, in meth
    return getattr(self._sock,name)(*args)
error: [Errno 111] Connection refused

[rospy.internal][INFO] 2022-02-23 12:05:48,634: topic[/rosout] removing connection to http://FM00351-u:35365/
[rospy.internal][WARNING] 2022-02-23 12:05:49,600: Unknown error initiating TCP/IP socket to FM00351-u:37723 (http://FM00351-u:34949/): Traceback (most recent call last):
  File "/opt/ros/melodic/lib/python2.7/dist-packages/rospy/impl/tcpros_base.py", line 562, in connect
    self.read_header()
  File "/opt/ros/melodic/lib/python2.7/dist-packages/rospy/impl/tcpros_base.py", line 657, in read_header
    self._validate_header(read_ros_handshake_header(sock, self.read_buff, self.protocol.buff_size))
  File "/opt/ros/melodic/lib/python2.7/dist-packages/rosgraph/network.py", line 357, in read_ros_handshake_header
    d = sock.recv(buff_size)
error: [Errno 104] Connection reset by peer

[rospy.internal][INFO] 2022-02-23 12:05:49,600: topic[/rosout] removing connection to http://FM00351-u:34949/
[rospy.internal][INFO] 2022-02-23 12:05:53,639: topic[/rosout] removing connection to /rosout
[rospy.core][INFO] 2022-02-23 12:14:57,452: signal_shutdown [signal-2]
[rospy.internal][INFO] 2022-02-23 12:14:57,457: topic[/rosout] removing connection to /rostopic_16397_1645617945169
[rospy.internal][INFO] 2022-02-23 12:14:57,459: topic[/rosout] removing connection to http://FM00351-u:41373/
[rospy.impl.masterslave][INFO] 2022-02-23 12:14:57,459: signal-2
[rospy.internal][WARNING] 2022-02-23 12:14:57,459: Unknown error initiating TCP/IP socket to FM00351-u:38175 (http://FM00351-u:41373/): Traceback (most recent call last):
  File "/opt/ros/melodic/lib/python2.7/dist-packages/rospy/impl/tcpros_base.py", line 561, in connect
    self.write_header()
  File "/opt/ros/melodic/lib/python2.7/dist-packages/rospy/impl/tcpros_base.py", line 642, in write_header
    self.stat_bytes += write_ros_handshake_header(sock, protocol.get_header_fields())
  File "/opt/ros/melodic/lib/python2.7/dist-packages/rosgraph/network.py", line 417, in write_ros_handshake_header
    sock.sendall(s)
  File "/usr/lib/python2.7/socket.py", line 228, in meth
    return getattr(self._sock,name)(*args)
  File "/usr/lib/python2.7/socket.py", line 174, in _dummy
    raise error(EBADF, 'Bad file descriptor')
error: [Errno 9] Bad file descriptor

[rospy.core][INFO] 2022-02-23 12:14:57,592: signal_shutdown [atexit]
