[rospy.client][INFO] 2022-02-23 12:25:01,368: init_node, name[/rostopic_1782_1645619101305], pid[1782]
[xmlrpc][INFO] 2022-02-23 12:25:01,369: XML-RPC server binding to 0.0.0.0:0
[xmlrpc][INFO] 2022-02-23 12:25:01,369: Started XML-RPC server [http://FM00351-u:39405/]
[rospy.init][INFO] 2022-02-23 12:25:01,369: ROS Slave URI: [http://FM00351-u:39405/]
[rospy.impl.masterslave][INFO] 2022-02-23 12:25:01,369: _ready: http://FM00351-u:39405/
[rospy.registration][INFO] 2022-02-23 12:25:01,370: Registering with master node http://localhost:11311
[xmlrpc][INFO] 2022-02-23 12:25:01,370: xml rpc node: starting XML-RPC server
[rospy.init][INFO] 2022-02-23 12:25:01,470: registered with master
[rospy.rosout][INFO] 2022-02-23 12:25:01,470: initializing /rosout core topic
[rospy.rosout][INFO] 2022-02-23 12:25:01,474: connected to core topic /rosout
[rospy.simtime][INFO] 2022-02-23 12:25:01,476: /use_sim_time is not set, will not subscribe to simulated time [/clock] topic
[rospy.internal][INFO] 2022-02-23 12:25:01,540: topic[/rosout] adding connection to [http://FM00351-u:42887/], count 0
[rospy.internal][INFO] 2022-02-23 12:25:01,542: topic[/rosout] adding connection to [http://FM00351-u:45997/], count 0
[rospy.internal][INFO] 2022-02-23 12:25:01,543: topic[/rosout] adding connection to [http://FM00351-u:39405/], count 2
[rospy.internal][INFO] 2022-02-23 12:25:01,545: topic[/rosout] adding connection to [/rostopic_1782_1645619101305], count 0
[rospy.internal][INFO] 2022-02-23 12:25:01,680: topic[/rosout] adding connection to [/rosout], count 1
[rospy.internal][INFO] 2022-02-23 12:25:07,707: topic[/rosout] adding connection to [http://FM00351-u:43837/], count 3
[rospy.internal][WARNING] 2022-02-23 12:25:23,061: Unknown error initiating TCP/IP socket to FM00351-u:46247 (http://FM00351-u:45997/): Traceback (most recent call last):
  File "/opt/ros/melodic/lib/python2.7/dist-packages/rospy/impl/tcpros_base.py", line 562, in connect
    self.read_header()
  File "/opt/ros/melodic/lib/python2.7/dist-packages/rospy/impl/tcpros_base.py", line 657, in read_header
    self._validate_header(read_ros_handshake_header(sock, self.read_buff, self.protocol.buff_size))
  File "/opt/ros/melodic/lib/python2.7/dist-packages/rosgraph/network.py", line 357, in read_ros_handshake_header
    d = sock.recv(buff_size)
error: [Errno 104] Connection reset by peer

[rospy.internal][INFO] 2022-02-23 12:25:23,062: topic[/rosout] removing connection to http://FM00351-u:45997/
[rospy.internal][ERROR] 2022-02-23 12:25:23,063: Unable to initiate TCP/IP socket to FM00351-u:44357 (http://FM00351-u:42887/): Traceback (most recent call last):
  File "/opt/ros/melodic/lib/python2.7/dist-packages/rospy/impl/tcpros_base.py", line 562, in connect
    self.read_header()
  File "/opt/ros/melodic/lib/python2.7/dist-packages/rospy/impl/tcpros_base.py", line 657, in read_header
    self._validate_header(read_ros_handshake_header(sock, self.read_buff, self.protocol.buff_size))
  File "/opt/ros/melodic/lib/python2.7/dist-packages/rospy/impl/tcpros_base.py", line 600, in _validate_header
    raise TransportInitError("remote error reported: %s"%header['error'])
TransportInitError: remote error reported: node shutting down

[rospy.internal][WARNING] 2022-02-23 12:25:24,065: Unknown error initiating TCP/IP socket to FM00351-u:44357 (http://FM00351-u:42887/): Traceback (most recent call last):
  File "/opt/ros/melodic/lib/python2.7/dist-packages/rospy/impl/tcpros_base.py", line 560, in connect
    self.socket.connect((dest_addr, dest_port))
  File "/usr/lib/python2.7/socket.py", line 228, in meth
    return getattr(self._sock,name)(*args)
error: [Errno 111] Connection refused

[rospy.internal][INFO] 2022-02-23 12:25:24,065: topic[/rosout] removing connection to http://FM00351-u:42887/
[rospy.internal][ERROR] 2022-02-23 12:25:24,230: Unable to initiate TCP/IP socket to FM00351-u:39121 (http://FM00351-u:43837/): Traceback (most recent call last):
  File "/opt/ros/melodic/lib/python2.7/dist-packages/rospy/impl/tcpros_base.py", line 562, in connect
    self.read_header()
  File "/opt/ros/melodic/lib/python2.7/dist-packages/rospy/impl/tcpros_base.py", line 657, in read_header
    self._validate_header(read_ros_handshake_header(sock, self.read_buff, self.protocol.buff_size))
  File "/opt/ros/melodic/lib/python2.7/dist-packages/rospy/impl/tcpros_base.py", line 600, in _validate_header
    raise TransportInitError("remote error reported: %s"%header['error'])
TransportInitError: remote error reported: node shutting down

[rospy.internal][WARNING] 2022-02-23 12:25:25,232: Unknown error initiating TCP/IP socket to FM00351-u:39121 (http://FM00351-u:43837/): Traceback (most recent call last):
  File "/opt/ros/melodic/lib/python2.7/dist-packages/rospy/impl/tcpros_base.py", line 560, in connect
    self.socket.connect((dest_addr, dest_port))
  File "/usr/lib/python2.7/socket.py", line 228, in meth
    return getattr(self._sock,name)(*args)
error: [Errno 111] Connection refused

[rospy.internal][INFO] 2022-02-23 12:25:25,232: topic[/rosout] removing connection to http://FM00351-u:43837/
[rospy.internal][INFO] 2022-02-23 12:25:40,356: topic[/rosout] removing connection to /rosout
[rospy.core][INFO] 2022-02-23 12:28:42,905: signal_shutdown [signal-2]
[rospy.internal][INFO] 2022-02-23 12:28:42,910: topic[/rosout] removing connection to /rostopic_1782_1645619101305
[rospy.internal][INFO] 2022-02-23 12:28:42,911: topic[/rosout] removing connection to http://FM00351-u:39405/
[rospy.impl.masterslave][INFO] 2022-02-23 12:28:42,911: signal-2
[rospy.internal][ERROR] 2022-02-23 12:28:42,911: Unable to initiate TCP/IP socket to FM00351-u:43279 (http://FM00351-u:39405/): Traceback (most recent call last):
  File "/opt/ros/melodic/lib/python2.7/dist-packages/rospy/impl/tcpros_base.py", line 562, in connect
    self.read_header()
  File "/opt/ros/melodic/lib/python2.7/dist-packages/rospy/impl/tcpros_base.py", line 657, in read_header
    self._validate_header(read_ros_handshake_header(sock, self.read_buff, self.protocol.buff_size))
  File "/opt/ros/melodic/lib/python2.7/dist-packages/rospy/impl/tcpros_base.py", line 600, in _validate_header
    raise TransportInitError("remote error reported: %s"%header['error'])
TransportInitError: remote error reported: node shutting down

[rospy.core][INFO] 2022-02-23 12:28:43,043: signal_shutdown [atexit]
