[rospy.client][INFO] 2022-02-23 12:22:46,622: init_node, name[/rostopic_1337_1645618966559], pid[1337]
[xmlrpc][INFO] 2022-02-23 12:22:46,623: XML-RPC server binding to 0.0.0.0:0
[xmlrpc][INFO] 2022-02-23 12:22:46,623: Started XML-RPC server [http://FM00351-u:42713/]
[rospy.init][INFO] 2022-02-23 12:22:46,623: ROS Slave URI: [http://FM00351-u:42713/]
[rospy.impl.masterslave][INFO] 2022-02-23 12:22:46,623: _ready: http://FM00351-u:42713/
[rospy.registration][INFO] 2022-02-23 12:22:46,623: Registering with master node http://localhost:11311
[xmlrpc][INFO] 2022-02-23 12:22:46,624: xml rpc node: starting XML-RPC server
[rospy.init][INFO] 2022-02-23 12:22:46,723: registered with master
[rospy.rosout][INFO] 2022-02-23 12:22:46,724: initializing /rosout core topic
[rospy.rosout][INFO] 2022-02-23 12:22:46,727: connected to core topic /rosout
[rospy.simtime][INFO] 2022-02-23 12:22:46,729: /use_sim_time is not set, will not subscribe to simulated time [/clock] topic
[rospy.internal][INFO] 2022-02-23 12:22:46,793: topic[/rosout] adding connection to [http://FM00351-u:43925/], count 0
[rospy.internal][INFO] 2022-02-23 12:22:46,795: topic[/rosout] adding connection to [http://FM00351-u:42839/], count 1
[rospy.internal][INFO] 2022-02-23 12:22:46,795: topic[/rosout] adding connection to [http://FM00351-u:42165/], count 1
[rospy.internal][INFO] 2022-02-23 12:22:46,798: topic[/rosout] adding connection to [http://FM00351-u:42713/], count 3
[rospy.internal][INFO] 2022-02-23 12:22:46,800: topic[/rosout] adding connection to [/rostopic_1337_1645618966559], count 0
[rospy.internal][INFO] 2022-02-23 12:22:46,973: topic[/rosout] adding connection to [/rosout], count 1
[rospy.internal][ERROR] 2022-02-23 12:22:59,477: Unable to initiate TCP/IP socket to FM00351-u:44697 (http://FM00351-u:42165/): Traceback (most recent call last):
  File "/opt/ros/melodic/lib/python2.7/dist-packages/rospy/impl/tcpros_base.py", line 562, in connect
    self.read_header()
  File "/opt/ros/melodic/lib/python2.7/dist-packages/rospy/impl/tcpros_base.py", line 657, in read_header
    self._validate_header(read_ros_handshake_header(sock, self.read_buff, self.protocol.buff_size))
  File "/opt/ros/melodic/lib/python2.7/dist-packages/rospy/impl/tcpros_base.py", line 600, in _validate_header
    raise TransportInitError("remote error reported: %s"%header['error'])
TransportInitError: remote error reported: node shutting down

[rospy.internal][WARNING] 2022-02-23 12:23:00,479: Unknown error initiating TCP/IP socket to FM00351-u:44697 (http://FM00351-u:42165/): Traceback (most recent call last):
  File "/opt/ros/melodic/lib/python2.7/dist-packages/rospy/impl/tcpros_base.py", line 560, in connect
    self.socket.connect((dest_addr, dest_port))
  File "/usr/lib/python2.7/socket.py", line 228, in meth
    return getattr(self._sock,name)(*args)
error: [Errno 111] Connection refused

[rospy.internal][INFO] 2022-02-23 12:23:00,479: topic[/rosout] removing connection to http://FM00351-u:42165/
[rospy.internal][INFO] 2022-02-23 12:23:01,834: topic[/rosout] adding connection to [http://FM00351-u:35073/], count 3
[rospy.internal][ERROR] 2022-02-23 12:23:15,522: Unable to initiate TCP/IP socket to FM00351-u:36611 (http://FM00351-u:35073/): Traceback (most recent call last):
  File "/opt/ros/melodic/lib/python2.7/dist-packages/rospy/impl/tcpros_base.py", line 562, in connect
    self.read_header()
  File "/opt/ros/melodic/lib/python2.7/dist-packages/rospy/impl/tcpros_base.py", line 657, in read_header
    self._validate_header(read_ros_handshake_header(sock, self.read_buff, self.protocol.buff_size))
  File "/opt/ros/melodic/lib/python2.7/dist-packages/rospy/impl/tcpros_base.py", line 600, in _validate_header
    raise TransportInitError("remote error reported: %s"%header['error'])
TransportInitError: remote error reported: node shutting down

[rospy.internal][WARNING] 2022-02-23 12:23:16,524: Unknown error initiating TCP/IP socket to FM00351-u:36611 (http://FM00351-u:35073/): Traceback (most recent call last):
  File "/opt/ros/melodic/lib/python2.7/dist-packages/rospy/impl/tcpros_base.py", line 560, in connect
    self.socket.connect((dest_addr, dest_port))
  File "/usr/lib/python2.7/socket.py", line 228, in meth
    return getattr(self._sock,name)(*args)
error: [Errno 111] Connection refused

[rospy.internal][INFO] 2022-02-23 12:23:16,525: topic[/rosout] removing connection to http://FM00351-u:35073/
[rospy.core][INFO] 2022-02-23 12:23:19,792: signal_shutdown [signal-2]
[rospy.internal][INFO] 2022-02-23 12:23:19,796: topic[/rosout] removing connection to /rostopic_1337_1645618966559
[rospy.internal][INFO] 2022-02-23 12:23:19,797: topic[/rosout] removing connection to /rosout
[rospy.internal][INFO] 2022-02-23 12:23:19,798: topic[/rosout] removing connection to http://FM00351-u:43925/
[rospy.internal][INFO] 2022-02-23 12:23:19,799: topic[/rosout] removing connection to http://FM00351-u:42839/
[rospy.internal][ERROR] 2022-02-23 12:23:19,799: Unable to initiate TCP/IP socket to FM00351-u:33287 (http://FM00351-u:42713/): Traceback (most recent call last):
  File "/opt/ros/melodic/lib/python2.7/dist-packages/rospy/impl/tcpros_base.py", line 562, in connect
    self.read_header()
  File "/opt/ros/melodic/lib/python2.7/dist-packages/rospy/impl/tcpros_base.py", line 657, in read_header
    self._validate_header(read_ros_handshake_header(sock, self.read_buff, self.protocol.buff_size))
  File "/opt/ros/melodic/lib/python2.7/dist-packages/rospy/impl/tcpros_base.py", line 600, in _validate_header
    raise TransportInitError("remote error reported: %s"%header['error'])
TransportInitError: remote error reported: node shutting down

[rospy.internal][INFO] 2022-02-23 12:23:19,799: topic[/rosout] removing connection to http://FM00351-u:42713/
[rospy.impl.masterslave][INFO] 2022-02-23 12:23:19,799: signal-2
[rospy.core][INFO] 2022-02-23 12:23:19,932: signal_shutdown [atexit]
